Exception on /follow/gabrieljhordane [POST]
Traceback (most recent call last):
  File "C:\Users\gabri\Desktop\Microblog\venv\lib\site-packages\flask\app.py", line 2073, in wsgi_app
    response = self.full_dispatch_request()
  File "C:\Users\gabri\Desktop\Microblog\venv\lib\site-packages\flask\app.py", line 1518, in full_dispatch_request
    rv = self.handle_user_exception(e)
  File "C:\Users\gabri\Desktop\Microblog\venv\lib\site-packages\flask\app.py", line 1516, in full_dispatch_request
    rv = self.dispatch_request()
  File "C:\Users\gabri\Desktop\Microblog\venv\lib\site-packages\flask\app.py", line 1502, in dispatch_request
    return self.ensure_sync(self.view_functions[rule.endpoint])(**req.view_args)
  File "C:\Users\gabri\Desktop\Microblog\venv\lib\site-packages\flask_login\utils.py", line 272, in decorated_view
    return func(*args, **kwargs)
  File "C:\Users\gabri\Desktop\Microblog\app\routes.py", line 120, in follow
    current_user.follow(user)
  File "C:\Users\gabri\Desktop\Microblog\app\models.py", line 45, in follow
    if not self.is_following(user):
  File "C:\Users\gabri\Desktop\Microblog\app\models.py", line 53, in is_following
    return self.followed.filter(followers.c.followed_id== user.id).count() > 0
AttributeError: 'str' object has no attribute 'id'
Microblog startup
Exception on /unfollow/gabrieljhordane [POST]
Traceback (most recent call last):
  File "C:\Users\gabri\Desktop\Microblog\venv\lib\site-packages\flask\app.py", line 2073, in wsgi_app
    response = self.full_dispatch_request()
  File "C:\Users\gabri\Desktop\Microblog\venv\lib\site-packages\flask\app.py", line 1518, in full_dispatch_request
    rv = self.handle_user_exception(e)
  File "C:\Users\gabri\Desktop\Microblog\venv\lib\site-packages\flask\app.py", line 1516, in full_dispatch_request
    rv = self.dispatch_request()
  File "C:\Users\gabri\Desktop\Microblog\venv\lib\site-packages\flask\app.py", line 1502, in dispatch_request
    return self.ensure_sync(self.view_functions[rule.endpoint])(**req.view_args)
  File "C:\Users\gabri\Desktop\Microblog\venv\lib\site-packages\flask_login\utils.py", line 272, in decorated_view
    return func(*args, **kwargs)
  File "C:\Users\gabri\Desktop\Microblog\app\routes.py", line 145, in unfollow
    current_user.unfollow(user)
AttributeError: 'User' object has no attribute 'unfollow'
Microblog startup
Microblog startup
Microblog startup
Microblog startup
Microblog startup
Microblog startup
Microblog startup
Microblog startup
Microblog startup
Exception on / [POST]
Traceback (most recent call last):
  File "C:\Users\gabri\Desktop\Microblog\venv\lib\site-packages\flask\app.py", line 2073, in wsgi_app
    response = self.full_dispatch_request()
  File "C:\Users\gabri\Desktop\Microblog\venv\lib\site-packages\flask\app.py", line 1518, in full_dispatch_request
    rv = self.handle_user_exception(e)
  File "C:\Users\gabri\Desktop\Microblog\venv\lib\site-packages\flask\app.py", line 1516, in full_dispatch_request
    rv = self.dispatch_request()
  File "C:\Users\gabri\Desktop\Microblog\venv\lib\site-packages\flask\app.py", line 1502, in dispatch_request
    return self.ensure_sync(self.view_functions[rule.endpoint])(**req.view_args)
  File "C:\Users\gabri\Desktop\Microblog\venv\lib\site-packages\flask_login\utils.py", line 272, in decorated_view
    return func(*args, **kwargs)
  File "C:\Users\gabri\Desktop\Microblog\app\routes.py", line 19, in index
    post = Post(body=form.post.data, athor=current_user)
  File "<string>", line 4, in __init__
  File "C:\Users\gabri\Desktop\Microblog\venv\lib\site-packages\sqlalchemy\orm\state.py", line 480, in _initialize_instance
    manager.dispatch.init_failure(self, args, kwargs)
  File "C:\Users\gabri\Desktop\Microblog\venv\lib\site-packages\sqlalchemy\util\langhelpers.py", line 70, in __exit__
    compat.raise_(
  File "C:\Users\gabri\Desktop\Microblog\venv\lib\site-packages\sqlalchemy\util\compat.py", line 207, in raise_
    raise exception
  File "C:\Users\gabri\Desktop\Microblog\venv\lib\site-packages\sqlalchemy\orm\state.py", line 477, in _initialize_instance
    return manager.original_init(*mixed[1:], **kwargs)
  File "C:\Users\gabri\Desktop\Microblog\venv\lib\site-packages\sqlalchemy\orm\decl_base.py", line 1154, in _declarative_constructor
    raise TypeError(
TypeError: 'athor' is an invalid keyword argument for Post
Microblog startup
Microblog startup
Exception on / [GET]
Traceback (most recent call last):
  File "C:\Users\gabri\Desktop\Microblog\venv\lib\site-packages\flask\app.py", line 2073, in wsgi_app
    response = self.full_dispatch_request()
  File "C:\Users\gabri\Desktop\Microblog\venv\lib\site-packages\flask\app.py", line 1518, in full_dispatch_request
    rv = self.handle_user_exception(e)
  File "C:\Users\gabri\Desktop\Microblog\venv\lib\site-packages\flask\app.py", line 1516, in full_dispatch_request
    rv = self.dispatch_request()
  File "C:\Users\gabri\Desktop\Microblog\venv\lib\site-packages\flask\app.py", line 1502, in dispatch_request
    return self.ensure_sync(self.view_functions[rule.endpoint])(**req.view_args)
  File "C:\Users\gabri\Desktop\Microblog\venv\lib\site-packages\flask_login\utils.py", line 272, in decorated_view
    return func(*args, **kwargs)
  File "C:\Users\gabri\Desktop\Microblog\app\routes.py", line 26, in index
    return render_template('index.html', title = 'Home', posts=posts, form=form)
  File "C:\Users\gabri\Desktop\Microblog\venv\lib\site-packages\flask\templating.py", line 147, in render_template
    return _render(
  File "C:\Users\gabri\Desktop\Microblog\venv\lib\site-packages\flask\templating.py", line 128, in _render
    rv = template.render(context)
  File "C:\Users\gabri\Desktop\Microblog\venv\lib\site-packages\jinja2\environment.py", line 1291, in render
    self.environment.handle_exception()
  File "C:\Users\gabri\Desktop\Microblog\venv\lib\site-packages\jinja2\environment.py", line 925, in handle_exception
    raise rewrite_traceback_stack(source=source)
  File "C:\Users\gabri\Desktop\Microblog\app\templates\index.html", line 1, in top-level template code
    {% extends 'base.html' %}
  File "C:\Users\gabri\Desktop\Microblog\app\templates\base.html", line 38, in top-level template code
    {% block content %} {% endblock %}
  File "C:\Users\gabri\Desktop\Microblog\app\templates\index.html", line 21, in block 'content'
    {% include '_post.html' %}
  File "C:\Users\gabri\Desktop\Microblog\app\templates\_post.html", line 3, in top-level template code
    <td><img src="{{ user.avatar(36) }}"></td>
  File "C:\Users\gabri\Desktop\Microblog\venv\lib\site-packages\jinja2\environment.py", line 474, in getattr
    return getattr(obj, attribute)
jinja2.exceptions.UndefinedError: 'user' is undefined
Exception on /explore [GET]
Traceback (most recent call last):
  File "C:\Users\gabri\Desktop\Microblog\venv\lib\site-packages\flask\app.py", line 2073, in wsgi_app
    response = self.full_dispatch_request()
  File "C:\Users\gabri\Desktop\Microblog\venv\lib\site-packages\flask\app.py", line 1518, in full_dispatch_request
    rv = self.handle_user_exception(e)
  File "C:\Users\gabri\Desktop\Microblog\venv\lib\site-packages\flask\app.py", line 1516, in full_dispatch_request
    rv = self.dispatch_request()
  File "C:\Users\gabri\Desktop\Microblog\venv\lib\site-packages\flask\app.py", line 1502, in dispatch_request
    return self.ensure_sync(self.view_functions[rule.endpoint])(**req.view_args)
  File "C:\Users\gabri\Desktop\Microblog\venv\lib\site-packages\flask_login\utils.py", line 272, in decorated_view
    return func(*args, **kwargs)
  File "C:\Users\gabri\Desktop\Microblog\app\routes.py", line 153, in explore
    return render_template('index.html', title='Explore', posts=posts)
  File "C:\Users\gabri\Desktop\Microblog\venv\lib\site-packages\flask\templating.py", line 147, in render_template
    return _render(
  File "C:\Users\gabri\Desktop\Microblog\venv\lib\site-packages\flask\templating.py", line 128, in _render
    rv = template.render(context)
  File "C:\Users\gabri\Desktop\Microblog\venv\lib\site-packages\jinja2\environment.py", line 1291, in render
    self.environment.handle_exception()
  File "C:\Users\gabri\Desktop\Microblog\venv\lib\site-packages\jinja2\environment.py", line 925, in handle_exception
    raise rewrite_traceback_stack(source=source)
  File "C:\Users\gabri\Desktop\Microblog\app\templates\index.html", line 1, in top-level template code
    {% extends 'base.html' %}
  File "C:\Users\gabri\Desktop\Microblog\app\templates\base.html", line 38, in top-level template code
    {% block content %} {% endblock %}
  File "C:\Users\gabri\Desktop\Microblog\app\templates\index.html", line 21, in block 'content'
    {% include '_post.html' %}
  File "C:\Users\gabri\Desktop\Microblog\app\templates\_post.html", line 3, in top-level template code
    <td><img src="{{ user.avatar(36) }}"></td>
  File "C:\Users\gabri\Desktop\Microblog\venv\lib\site-packages\jinja2\environment.py", line 474, in getattr
    return getattr(obj, attribute)
jinja2.exceptions.UndefinedError: 'user' is undefined
Microblog startup
Microblog startup
