Microblog startup
Exception on /edit_profile [POST]
Traceback (most recent call last):
  File "C:\Users\gabri\Desktop\Microblog\venv\lib\site-packages\sqlalchemy\engine\base.py", line 1802, in _execute_context
    self.dialect.do_execute(
  File "C:\Users\gabri\Desktop\Microblog\venv\lib\site-packages\sqlalchemy\engine\default.py", line 732, in do_execute
    cursor.execute(statement, parameters)
sqlite3.IntegrityError: UNIQUE constraint failed: user.username

The above exception was the direct cause of the following exception:

Traceback (most recent call last):
  File "C:\Users\gabri\Desktop\Microblog\venv\lib\site-packages\flask\app.py", line 2073, in wsgi_app
    response = self.full_dispatch_request()
  File "C:\Users\gabri\Desktop\Microblog\venv\lib\site-packages\flask\app.py", line 1518, in full_dispatch_request
    rv = self.handle_user_exception(e)
  File "C:\Users\gabri\Desktop\Microblog\venv\lib\site-packages\flask\app.py", line 1516, in full_dispatch_request
    rv = self.dispatch_request()
  File "C:\Users\gabri\Desktop\Microblog\venv\lib\site-packages\flask\app.py", line 1502, in dispatch_request
    return self.ensure_sync(self.view_functions[rule.endpoint])(**req.view_args)
  File "C:\Users\gabri\Desktop\Microblog\app\routes.py", line 97, in edit_profile
    db.session.commit()
  File "<string>", line 2, in commit
  File "C:\Users\gabri\Desktop\Microblog\venv\lib\site-packages\sqlalchemy\orm\session.py", line 1431, in commit
    self._transaction.commit(_to_root=self.future)
  File "C:\Users\gabri\Desktop\Microblog\venv\lib\site-packages\sqlalchemy\orm\session.py", line 829, in commit
    self._prepare_impl()
  File "C:\Users\gabri\Desktop\Microblog\venv\lib\site-packages\sqlalchemy\orm\session.py", line 808, in _prepare_impl
    self.session.flush()
  File "C:\Users\gabri\Desktop\Microblog\venv\lib\site-packages\sqlalchemy\orm\session.py", line 3363, in flush
    self._flush(objects)
  File "C:\Users\gabri\Desktop\Microblog\venv\lib\site-packages\sqlalchemy\orm\session.py", line 3503, in _flush
    transaction.rollback(_capture_exception=True)
  File "C:\Users\gabri\Desktop\Microblog\venv\lib\site-packages\sqlalchemy\util\langhelpers.py", line 70, in __exit__
    compat.raise_(
  File "C:\Users\gabri\Desktop\Microblog\venv\lib\site-packages\sqlalchemy\util\compat.py", line 207, in raise_
    raise exception
  File "C:\Users\gabri\Desktop\Microblog\venv\lib\site-packages\sqlalchemy\orm\session.py", line 3463, in _flush
    flush_context.execute()
  File "C:\Users\gabri\Desktop\Microblog\venv\lib\site-packages\sqlalchemy\orm\unitofwork.py", line 456, in execute
    rec.execute(self)
  File "C:\Users\gabri\Desktop\Microblog\venv\lib\site-packages\sqlalchemy\orm\unitofwork.py", line 630, in execute
    util.preloaded.orm_persistence.save_obj(
  File "C:\Users\gabri\Desktop\Microblog\venv\lib\site-packages\sqlalchemy\orm\persistence.py", line 236, in save_obj
    _emit_update_statements(
  File "C:\Users\gabri\Desktop\Microblog\venv\lib\site-packages\sqlalchemy\orm\persistence.py", line 1000, in _emit_update_statements
    c = connection._execute_20(
  File "C:\Users\gabri\Desktop\Microblog\venv\lib\site-packages\sqlalchemy\engine\base.py", line 1614, in _execute_20
    return meth(self, args_10style, kwargs_10style, execution_options)
  File "C:\Users\gabri\Desktop\Microblog\venv\lib\site-packages\sqlalchemy\sql\elements.py", line 325, in _execute_on_connection
    return connection._execute_clauseelement(
  File "C:\Users\gabri\Desktop\Microblog\venv\lib\site-packages\sqlalchemy\engine\base.py", line 1481, in _execute_clauseelement
    ret = self._execute_context(
  File "C:\Users\gabri\Desktop\Microblog\venv\lib\site-packages\sqlalchemy\engine\base.py", line 1845, in _execute_context
    self._handle_dbapi_exception(
  File "C:\Users\gabri\Desktop\Microblog\venv\lib\site-packages\sqlalchemy\engine\base.py", line 2026, in _handle_dbapi_exception
    util.raise_(
  File "C:\Users\gabri\Desktop\Microblog\venv\lib\site-packages\sqlalchemy\util\compat.py", line 207, in raise_
    raise exception
  File "C:\Users\gabri\Desktop\Microblog\venv\lib\site-packages\sqlalchemy\engine\base.py", line 1802, in _execute_context
    self.dialect.do_execute(
  File "C:\Users\gabri\Desktop\Microblog\venv\lib\site-packages\sqlalchemy\engine\default.py", line 732, in do_execute
    cursor.execute(statement, parameters)
sqlalchemy.exc.IntegrityError: (sqlite3.IntegrityError) UNIQUE constraint failed: user.username
[SQL: UPDATE user SET username=?, about=? WHERE user.id = ?]
[parameters: ('gabrieljhordan', '', 2)]
(Background on this error at: https://sqlalche.me/e/14/gkpj)
Microblog startup
Microblog startup
Microblog startup
Microblog startup
Exception on /login [POST]
Traceback (most recent call last):
  File "C:\Users\gabri\Desktop\Microblog\venv\lib\site-packages\flask\app.py", line 2073, in wsgi_app
    response = self.full_dispatch_request()
  File "C:\Users\gabri\Desktop\Microblog\venv\lib\site-packages\flask\app.py", line 1518, in full_dispatch_request
    rv = self.handle_user_exception(e)
  File "C:\Users\gabri\Desktop\Microblog\venv\lib\site-packages\flask\app.py", line 1516, in full_dispatch_request
    rv = self.dispatch_request()
  File "C:\Users\gabri\Desktop\Microblog\venv\lib\site-packages\flask\app.py", line 1502, in dispatch_request
    return self.ensure_sync(self.view_functions[rule.endpoint])(**req.view_args)
  File "C:\Users\gabri\Desktop\Microblog\app\routes.py", line 39, in login
    user = User.query.filter_by(username=form.username.data).first()
  File "C:\Users\gabri\Desktop\Microblog\venv\lib\site-packages\flask_sqlalchemy\__init__.py", line 550, in __get__
    mapper = orm.class_mapper(type)
  File "C:\Users\gabri\Desktop\Microblog\venv\lib\site-packages\sqlalchemy\orm\base.py", line 442, in class_mapper
    mapper = _inspect_mapped_class(class_, configure=configure)
  File "C:\Users\gabri\Desktop\Microblog\venv\lib\site-packages\sqlalchemy\orm\base.py", line 421, in _inspect_mapped_class
    mapper._check_configure()
  File "C:\Users\gabri\Desktop\Microblog\venv\lib\site-packages\sqlalchemy\orm\mapper.py", line 1900, in _check_configure
    _configure_registries({self.registry}, cascade=True)
  File "C:\Users\gabri\Desktop\Microblog\venv\lib\site-packages\sqlalchemy\orm\mapper.py", line 3418, in _configure_registries
    _do_configure_registries(registries, cascade)
  File "C:\Users\gabri\Desktop\Microblog\venv\lib\site-packages\sqlalchemy\orm\mapper.py", line 3457, in _do_configure_registries
    mapper._post_configure_properties()
  File "C:\Users\gabri\Desktop\Microblog\venv\lib\site-packages\sqlalchemy\orm\mapper.py", line 1917, in _post_configure_properties
    prop.init()
  File "C:\Users\gabri\Desktop\Microblog\venv\lib\site-packages\sqlalchemy\orm\interfaces.py", line 231, in init
    self.do_init()
  File "C:\Users\gabri\Desktop\Microblog\venv\lib\site-packages\sqlalchemy\orm\relationships.py", line 2155, in do_init
    self._generate_backref()
  File "C:\Users\gabri\Desktop\Microblog\venv\lib\site-packages\sqlalchemy\orm\relationships.py", line 2435, in _generate_backref
    raise sa_exc.ArgumentError(
sqlalchemy.exc.ArgumentError: Error creating backref 'followers' on relationship 'User.followers': property of that name exists on mapper 'mapped class User->user'
Microblog startup
Microblog startup
Microblog startup
Microblog startup
Microblog startup
Microblog startup
Microblog startup
Microblog startup
Microblog startup
Microblog startup
Microblog startup
Microblog startup
Microblog startup
Microblog startup
Microblog startup
Microblog startup
Microblog startup
Microblog startup
Microblog startup
Microblog startup
Microblog startup
Microblog startup
Microblog startup
Microblog startup
Microblog startup
Microblog startup
Microblog startup
Microblog startup
Microblog startup
Microblog startup
Microblog startup
Microblog startup
